[2024-07-10T03:23:33.021+0000] {local_task_job_runner.py:120} INFO - ::group::Pre task execution logs
[2024-07-10T03:23:33.049+0000] {taskinstance.py:2076} INFO - Dependencies all met for dep_context=non-requeueable deps ti=<TaskInstance: first_task.transfer_task scheduled__2024-07-09T00:00:00+00:00 [queued]>
[2024-07-10T03:23:33.055+0000] {taskinstance.py:2076} INFO - Dependencies all met for dep_context=requeueable deps ti=<TaskInstance: first_task.transfer_task scheduled__2024-07-09T00:00:00+00:00 [queued]>
[2024-07-10T03:23:33.055+0000] {taskinstance.py:2306} INFO - Starting attempt 1 of 1
[2024-07-10T03:23:33.067+0000] {taskinstance.py:2330} INFO - Executing <Task(PythonOperator): transfer_task> on 2024-07-09 00:00:00+00:00
[2024-07-10T03:23:33.072+0000] {standard_task_runner.py:90} INFO - Running: ['***', 'tasks', 'run', 'first_task', 'transfer_task', 'scheduled__2024-07-09T00:00:00+00:00', '--job-id', '5', '--raw', '--subdir', 'DAGS_FOLDER/first_dag.py', '--cfg-path', '/tmp/tmpb2i2st41']
[2024-07-10T03:23:33.074+0000] {standard_task_runner.py:91} INFO - Job 5: Subtask transfer_task
[2024-07-10T03:23:33.075+0000] {logging_mixin.py:188} WARNING - /home/***/.local/lib/python3.12/site-packages/***/task/task_runner/standard_task_runner.py:61 DeprecationWarning: This process (pid=205) is multi-threaded, use of fork() may lead to deadlocks in the child.
[2024-07-10T03:23:33.075+0000] {standard_task_runner.py:63} INFO - Started process 207 to run task
[2024-07-10T03:23:33.107+0000] {task_command.py:426} INFO - Running <TaskInstance: first_task.transfer_task scheduled__2024-07-09T00:00:00+00:00 [running]> on host a4cfe2dbe055
[2024-07-10T03:23:33.168+0000] {taskinstance.py:2648} INFO - Exporting env vars: AIRFLOW_CTX_DAG_OWNER='***' AIRFLOW_CTX_DAG_ID='first_task' AIRFLOW_CTX_TASK_ID='transfer_task' AIRFLOW_CTX_EXECUTION_DATE='2024-07-09T00:00:00+00:00' AIRFLOW_CTX_TRY_NUMBER='1' AIRFLOW_CTX_DAG_RUN_ID='scheduled__2024-07-09T00:00:00+00:00'
[2024-07-10T03:23:33.169+0000] {taskinstance.py:430} INFO - ::endgroup::
[2024-07-10T03:23:36.421+0000] {taskinstance.py:441} INFO - ::group::Post task execution logs
[2024-07-10T03:23:36.422+0000] {taskinstance.py:2905} ERROR - Task failed with exception
Traceback (most recent call last):
  File "/home/airflow/.local/lib/python3.12/site-packages/airflow/models/taskinstance.py", line 465, in _execute_task
    result = _execute_callable(context=context, **execute_callable_kwargs)
             ^^^^^^^^^^^^^^^^^^^^^^^^^^^^^^^^^^^^^^^^^^^^^^^^^^^^^^^^^^^^^
  File "/home/airflow/.local/lib/python3.12/site-packages/airflow/models/taskinstance.py", line 432, in _execute_callable
    return execute_callable(context=context, **execute_callable_kwargs)
           ^^^^^^^^^^^^^^^^^^^^^^^^^^^^^^^^^^^^^^^^^^^^^^^^^^^^^^^^^^^^
  File "/home/airflow/.local/lib/python3.12/site-packages/airflow/models/baseoperator.py", line 401, in wrapper
    return func(self, *args, **kwargs)
           ^^^^^^^^^^^^^^^^^^^^^^^^^^^
  File "/home/airflow/.local/lib/python3.12/site-packages/airflow/operators/python.py", line 235, in execute
    return_value = self.execute_callable()
                   ^^^^^^^^^^^^^^^^^^^^^^^
  File "/home/airflow/.local/lib/python3.12/site-packages/airflow/operators/python.py", line 252, in execute_callable
    return self.python_callable(*self.op_args, **self.op_kwargs)
           ^^^^^^^^^^^^^^^^^^^^^^^^^^^^^^^^^^^^^^^^^^^^^^^^^^^^^
  File "/opt/airflow/dags/first_dag.py", line 32, in run_elt_script
    raise Exception(f"Script failed with error: {result.stderr}")
Exception: Script failed with error: Traceback (most recent call last):
  File "/opt/***/etl_script/etl_script.py", line 26, in <module>
    tables = os.listdir("/home/mihir/Downloads/ETL Pipeline/etl_pipeline/models/Tables")
             ^^^^^^^^^^^^^^^^^^^^^^^^^^^^^^^^^^^^^^^^^^^^^^^^^^^^^^^^^^^^^^^^^^^^^^^^^^^
FileNotFoundError: [Errno 2] No such file or directory: '/home/mihir/Downloads/ETL Pipeline/etl_pipeline/models/Tables'

[2024-07-10T03:23:36.428+0000] {taskinstance.py:1206} INFO - Marking task as FAILED. dag_id=first_task, task_id=transfer_task, run_id=scheduled__2024-07-09T00:00:00+00:00, execution_date=20240709T000000, start_date=20240710T032333, end_date=20240710T032336
[2024-07-10T03:23:36.438+0000] {standard_task_runner.py:110} ERROR - Failed to execute job 5 for task transfer_task (Script failed with error: Traceback (most recent call last):
  File "/opt/***/etl_script/etl_script.py", line 26, in <module>
    tables = os.listdir("/home/mihir/Downloads/ETL Pipeline/etl_pipeline/models/Tables")
             ^^^^^^^^^^^^^^^^^^^^^^^^^^^^^^^^^^^^^^^^^^^^^^^^^^^^^^^^^^^^^^^^^^^^^^^^^^^
FileNotFoundError: [Errno 2] No such file or directory: '/home/mihir/Downloads/ETL Pipeline/etl_pipeline/models/Tables'
; 207)
[2024-07-10T03:23:36.458+0000] {local_task_job_runner.py:240} INFO - Task exited with return code 1
[2024-07-10T03:23:36.470+0000] {taskinstance.py:3503} INFO - 0 downstream tasks scheduled from follow-on schedule check
[2024-07-10T03:23:36.473+0000] {local_task_job_runner.py:222} INFO - ::endgroup::
