[2024-07-10T04:05:52.837+0000] {local_task_job_runner.py:120} INFO - ::group::Pre task execution logs
[2024-07-10T04:05:52.870+0000] {taskinstance.py:2076} INFO - Dependencies all met for dep_context=non-requeueable deps ti=<TaskInstance: etl_pipeline.transfer_task manual__2024-07-10T04:05:24.228173+00:00 [queued]>
[2024-07-10T04:05:52.881+0000] {taskinstance.py:2076} INFO - Dependencies all met for dep_context=requeueable deps ti=<TaskInstance: etl_pipeline.transfer_task manual__2024-07-10T04:05:24.228173+00:00 [queued]>
[2024-07-10T04:05:52.881+0000] {taskinstance.py:2306} INFO - Starting attempt 1 of 1
[2024-07-10T04:05:52.902+0000] {taskinstance.py:2330} INFO - Executing <Task(PythonOperator): transfer_task> on 2024-07-10 04:05:24.228173+00:00
[2024-07-10T04:05:52.908+0000] {standard_task_runner.py:90} INFO - Running: ['***', 'tasks', 'run', 'etl_pipeline', 'transfer_task', 'manual__2024-07-10T04:05:24.228173+00:00', '--job-id', '5', '--raw', '--subdir', 'DAGS_FOLDER/first_dag.py', '--cfg-path', '/tmp/tmpfrvr9a6r']
[2024-07-10T04:05:52.910+0000] {standard_task_runner.py:91} INFO - Job 5: Subtask transfer_task
[2024-07-10T04:05:52.911+0000] {logging_mixin.py:188} WARNING - /home/***/.local/lib/python3.12/site-packages/***/task/task_runner/standard_task_runner.py:61 DeprecationWarning: This process (pid=194) is multi-threaded, use of fork() may lead to deadlocks in the child.
[2024-07-10T04:05:52.911+0000] {standard_task_runner.py:63} INFO - Started process 195 to run task
[2024-07-10T04:05:52.950+0000] {task_command.py:426} INFO - Running <TaskInstance: etl_pipeline.transfer_task manual__2024-07-10T04:05:24.228173+00:00 [running]> on host f0c32192715b
[2024-07-10T04:05:53.027+0000] {taskinstance.py:2648} INFO - Exporting env vars: AIRFLOW_CTX_DAG_OWNER='***' AIRFLOW_CTX_DAG_ID='etl_pipeline' AIRFLOW_CTX_TASK_ID='transfer_task' AIRFLOW_CTX_EXECUTION_DATE='2024-07-10T04:05:24.228173+00:00' AIRFLOW_CTX_TRY_NUMBER='1' AIRFLOW_CTX_DAG_RUN_ID='manual__2024-07-10T04:05:24.228173+00:00'
[2024-07-10T04:05:53.027+0000] {taskinstance.py:430} INFO - ::endgroup::
[2024-07-10T04:06:00.579+0000] {taskinstance.py:441} INFO - ::group::Post task execution logs
[2024-07-10T04:06:00.580+0000] {taskinstance.py:2905} ERROR - Task failed with exception
Traceback (most recent call last):
  File "/home/airflow/.local/lib/python3.12/site-packages/airflow/models/taskinstance.py", line 465, in _execute_task
    result = _execute_callable(context=context, **execute_callable_kwargs)
             ^^^^^^^^^^^^^^^^^^^^^^^^^^^^^^^^^^^^^^^^^^^^^^^^^^^^^^^^^^^^^
  File "/home/airflow/.local/lib/python3.12/site-packages/airflow/models/taskinstance.py", line 432, in _execute_callable
    return execute_callable(context=context, **execute_callable_kwargs)
           ^^^^^^^^^^^^^^^^^^^^^^^^^^^^^^^^^^^^^^^^^^^^^^^^^^^^^^^^^^^^
  File "/home/airflow/.local/lib/python3.12/site-packages/airflow/models/baseoperator.py", line 401, in wrapper
    return func(self, *args, **kwargs)
           ^^^^^^^^^^^^^^^^^^^^^^^^^^^
  File "/home/airflow/.local/lib/python3.12/site-packages/airflow/operators/python.py", line 235, in execute
    return_value = self.execute_callable()
                   ^^^^^^^^^^^^^^^^^^^^^^^
  File "/home/airflow/.local/lib/python3.12/site-packages/airflow/operators/python.py", line 252, in execute_callable
    return self.python_callable(*self.op_args, **self.op_kwargs)
           ^^^^^^^^^^^^^^^^^^^^^^^^^^^^^^^^^^^^^^^^^^^^^^^^^^^^^
  File "/opt/airflow/dags/first_dag.py", line 32, in run_etl_script
    raise Exception(f"Script failed with error: {result.stderr}")
Exception: Script failed with error: Traceback (most recent call last):
  File "/opt/***/etl_script/etl_script.py", line 45, in <module>
    with open(output_file, 'w', newline='') as f:
         ^^^^^^^^^^^^^^^^^^^^^^^^^^^^^^^^^^
PermissionError: [Errno 13] Permission denied: '/opt/***/etl_script/data/partsupp.csv'

[2024-07-10T04:06:00.587+0000] {taskinstance.py:1206} INFO - Marking task as FAILED. dag_id=etl_pipeline, task_id=transfer_task, run_id=manual__2024-07-10T04:05:24.228173+00:00, execution_date=20240710T040524, start_date=20240710T040552, end_date=20240710T040600
[2024-07-10T04:06:00.598+0000] {standard_task_runner.py:110} ERROR - Failed to execute job 5 for task transfer_task (Script failed with error: Traceback (most recent call last):
  File "/opt/***/etl_script/etl_script.py", line 45, in <module>
    with open(output_file, 'w', newline='') as f:
         ^^^^^^^^^^^^^^^^^^^^^^^^^^^^^^^^^^
PermissionError: [Errno 13] Permission denied: '/opt/***/etl_script/data/partsupp.csv'
; 195)
[2024-07-10T04:06:00.619+0000] {local_task_job_runner.py:240} INFO - Task exited with return code 1
[2024-07-10T04:06:00.630+0000] {taskinstance.py:3503} INFO - 0 downstream tasks scheduled from follow-on schedule check
[2024-07-10T04:06:00.633+0000] {local_task_job_runner.py:222} INFO - ::endgroup::
