[2024-07-10T03:34:08.128+0000] {local_task_job_runner.py:120} INFO - ::group::Pre task execution logs
[2024-07-10T03:34:08.155+0000] {taskinstance.py:2076} INFO - Dependencies all met for dep_context=non-requeueable deps ti=<TaskInstance: etl_pipeline.transfer_task scheduled__2024-07-09T00:00:00+00:00 [queued]>
[2024-07-10T03:34:08.161+0000] {taskinstance.py:2076} INFO - Dependencies all met for dep_context=requeueable deps ti=<TaskInstance: etl_pipeline.transfer_task scheduled__2024-07-09T00:00:00+00:00 [queued]>
[2024-07-10T03:34:08.162+0000] {taskinstance.py:2306} INFO - Starting attempt 1 of 1
[2024-07-10T03:34:08.173+0000] {taskinstance.py:2330} INFO - Executing <Task(PythonOperator): transfer_task> on 2024-07-09 00:00:00+00:00
[2024-07-10T03:34:08.178+0000] {standard_task_runner.py:90} INFO - Running: ['***', 'tasks', 'run', 'etl_pipeline', 'transfer_task', 'scheduled__2024-07-09T00:00:00+00:00', '--job-id', '10', '--raw', '--subdir', 'DAGS_FOLDER/first_dag.py', '--cfg-path', '/tmp/tmp8s3lzcyv']
[2024-07-10T03:34:08.180+0000] {standard_task_runner.py:91} INFO - Job 10: Subtask transfer_task
[2024-07-10T03:34:08.181+0000] {logging_mixin.py:188} WARNING - /home/***/.local/lib/python3.12/site-packages/***/task/task_runner/standard_task_runner.py:61 DeprecationWarning: This process (pid=470) is multi-threaded, use of fork() may lead to deadlocks in the child.
[2024-07-10T03:34:08.181+0000] {standard_task_runner.py:63} INFO - Started process 473 to run task
[2024-07-10T03:34:08.211+0000] {task_command.py:426} INFO - Running <TaskInstance: etl_pipeline.transfer_task scheduled__2024-07-09T00:00:00+00:00 [running]> on host a4cfe2dbe055
[2024-07-10T03:34:08.269+0000] {taskinstance.py:2648} INFO - Exporting env vars: AIRFLOW_CTX_DAG_OWNER='***' AIRFLOW_CTX_DAG_ID='etl_pipeline' AIRFLOW_CTX_TASK_ID='transfer_task' AIRFLOW_CTX_EXECUTION_DATE='2024-07-09T00:00:00+00:00' AIRFLOW_CTX_TRY_NUMBER='1' AIRFLOW_CTX_DAG_RUN_ID='scheduled__2024-07-09T00:00:00+00:00'
[2024-07-10T03:34:08.270+0000] {taskinstance.py:430} INFO - ::endgroup::
[2024-07-10T03:34:10.154+0000] {taskinstance.py:441} INFO - ::group::Post task execution logs
[2024-07-10T03:34:10.154+0000] {taskinstance.py:2905} ERROR - Task failed with exception
Traceback (most recent call last):
  File "/home/airflow/.local/lib/python3.12/site-packages/airflow/models/taskinstance.py", line 465, in _execute_task
    result = _execute_callable(context=context, **execute_callable_kwargs)
             ^^^^^^^^^^^^^^^^^^^^^^^^^^^^^^^^^^^^^^^^^^^^^^^^^^^^^^^^^^^^^
  File "/home/airflow/.local/lib/python3.12/site-packages/airflow/models/taskinstance.py", line 432, in _execute_callable
    return execute_callable(context=context, **execute_callable_kwargs)
           ^^^^^^^^^^^^^^^^^^^^^^^^^^^^^^^^^^^^^^^^^^^^^^^^^^^^^^^^^^^^
  File "/home/airflow/.local/lib/python3.12/site-packages/airflow/models/baseoperator.py", line 401, in wrapper
    return func(self, *args, **kwargs)
           ^^^^^^^^^^^^^^^^^^^^^^^^^^^
  File "/home/airflow/.local/lib/python3.12/site-packages/airflow/operators/python.py", line 235, in execute
    return_value = self.execute_callable()
                   ^^^^^^^^^^^^^^^^^^^^^^^
  File "/home/airflow/.local/lib/python3.12/site-packages/airflow/operators/python.py", line 252, in execute_callable
    return self.python_callable(*self.op_args, **self.op_kwargs)
           ^^^^^^^^^^^^^^^^^^^^^^^^^^^^^^^^^^^^^^^^^^^^^^^^^^^^^
  File "/opt/airflow/dags/first_dag.py", line 32, in run_etl_script
    raise Exception(f"Script failed with error: {result.stderr}")
Exception: Script failed with error: Traceback (most recent call last):
  File "/opt/***/etl_script/etl_script.py", line 26, in <module>
    tables = os.listdir("/opt/***/dbt/models/Tables")
             ^^^^^^^^^^^^^^^^^^^^^^^^^^^^^^^^^^^^^^^^^^^^
FileNotFoundError: [Errno 2] No such file or directory: '/opt/***/dbt/models/Tables'

[2024-07-10T03:34:10.161+0000] {taskinstance.py:1206} INFO - Marking task as FAILED. dag_id=etl_pipeline, task_id=transfer_task, run_id=scheduled__2024-07-09T00:00:00+00:00, execution_date=20240709T000000, start_date=20240710T033408, end_date=20240710T033410
[2024-07-10T03:34:10.177+0000] {standard_task_runner.py:110} ERROR - Failed to execute job 10 for task transfer_task (Script failed with error: Traceback (most recent call last):
  File "/opt/***/etl_script/etl_script.py", line 26, in <module>
    tables = os.listdir("/opt/***/dbt/models/Tables")
             ^^^^^^^^^^^^^^^^^^^^^^^^^^^^^^^^^^^^^^^^^^^^
FileNotFoundError: [Errno 2] No such file or directory: '/opt/***/dbt/models/Tables'
; 473)
[2024-07-10T03:34:10.198+0000] {local_task_job_runner.py:240} INFO - Task exited with return code 1
[2024-07-10T03:34:10.210+0000] {taskinstance.py:3503} INFO - 0 downstream tasks scheduled from follow-on schedule check
[2024-07-10T03:34:10.213+0000] {local_task_job_runner.py:222} INFO - ::endgroup::
[2024-07-10T03:58:25.954+0000] {local_task_job_runner.py:120} INFO - ::group::Pre task execution logs
[2024-07-10T03:58:25.982+0000] {taskinstance.py:2076} INFO - Dependencies all met for dep_context=non-requeueable deps ti=<TaskInstance: etl_pipeline.transfer_task scheduled__2024-07-09T00:00:00+00:00 [queued]>
[2024-07-10T03:58:25.988+0000] {taskinstance.py:2076} INFO - Dependencies all met for dep_context=requeueable deps ti=<TaskInstance: etl_pipeline.transfer_task scheduled__2024-07-09T00:00:00+00:00 [queued]>
[2024-07-10T03:58:25.989+0000] {taskinstance.py:2306} INFO - Starting attempt 1 of 1
[2024-07-10T03:58:25.998+0000] {taskinstance.py:2330} INFO - Executing <Task(PythonOperator): transfer_task> on 2024-07-09 00:00:00+00:00
[2024-07-10T03:58:26.003+0000] {standard_task_runner.py:90} INFO - Running: ['***', 'tasks', 'run', 'etl_pipeline', 'transfer_task', 'scheduled__2024-07-09T00:00:00+00:00', '--job-id', '5', '--raw', '--subdir', 'DAGS_FOLDER/first_dag.py', '--cfg-path', '/tmp/tmpvbvu_3b2']
[2024-07-10T03:58:26.005+0000] {standard_task_runner.py:91} INFO - Job 5: Subtask transfer_task
[2024-07-10T03:58:26.006+0000] {logging_mixin.py:188} WARNING - /home/***/.local/lib/python3.12/site-packages/***/task/task_runner/standard_task_runner.py:61 DeprecationWarning: This process (pid=200) is multi-threaded, use of fork() may lead to deadlocks in the child.
[2024-07-10T03:58:26.006+0000] {standard_task_runner.py:63} INFO - Started process 202 to run task
[2024-07-10T03:58:26.037+0000] {task_command.py:426} INFO - Running <TaskInstance: etl_pipeline.transfer_task scheduled__2024-07-09T00:00:00+00:00 [running]> on host c2493467fa79
[2024-07-10T03:58:26.096+0000] {taskinstance.py:2648} INFO - Exporting env vars: AIRFLOW_CTX_DAG_OWNER='***' AIRFLOW_CTX_DAG_ID='etl_pipeline' AIRFLOW_CTX_TASK_ID='transfer_task' AIRFLOW_CTX_EXECUTION_DATE='2024-07-09T00:00:00+00:00' AIRFLOW_CTX_TRY_NUMBER='1' AIRFLOW_CTX_DAG_RUN_ID='scheduled__2024-07-09T00:00:00+00:00'
[2024-07-10T03:58:26.096+0000] {taskinstance.py:430} INFO - ::endgroup::
[2024-07-10T03:58:33.259+0000] {taskinstance.py:441} INFO - ::group::Post task execution logs
[2024-07-10T03:58:33.260+0000] {taskinstance.py:2905} ERROR - Task failed with exception
Traceback (most recent call last):
  File "/home/airflow/.local/lib/python3.12/site-packages/airflow/models/taskinstance.py", line 465, in _execute_task
    result = _execute_callable(context=context, **execute_callable_kwargs)
             ^^^^^^^^^^^^^^^^^^^^^^^^^^^^^^^^^^^^^^^^^^^^^^^^^^^^^^^^^^^^^
  File "/home/airflow/.local/lib/python3.12/site-packages/airflow/models/taskinstance.py", line 432, in _execute_callable
    return execute_callable(context=context, **execute_callable_kwargs)
           ^^^^^^^^^^^^^^^^^^^^^^^^^^^^^^^^^^^^^^^^^^^^^^^^^^^^^^^^^^^^
  File "/home/airflow/.local/lib/python3.12/site-packages/airflow/models/baseoperator.py", line 401, in wrapper
    return func(self, *args, **kwargs)
           ^^^^^^^^^^^^^^^^^^^^^^^^^^^
  File "/home/airflow/.local/lib/python3.12/site-packages/airflow/operators/python.py", line 235, in execute
    return_value = self.execute_callable()
                   ^^^^^^^^^^^^^^^^^^^^^^^
  File "/home/airflow/.local/lib/python3.12/site-packages/airflow/operators/python.py", line 252, in execute_callable
    return self.python_callable(*self.op_args, **self.op_kwargs)
           ^^^^^^^^^^^^^^^^^^^^^^^^^^^^^^^^^^^^^^^^^^^^^^^^^^^^^
  File "/opt/airflow/dags/first_dag.py", line 32, in run_etl_script
    raise Exception(f"Script failed with error: {result.stderr}")
Exception: Script failed with error: Traceback (most recent call last):
  File "/opt/***/etl_script/etl_script.py", line 42, in <module>
    with open(output_file, 'w', newline='') as f:
         ^^^^^^^^^^^^^^^^^^^^^^^^^^^^^^^^^^
FileNotFoundError: [Errno 2] No such file or directory: 'data/partsupp.csv'

[2024-07-10T03:58:33.267+0000] {taskinstance.py:1206} INFO - Marking task as FAILED. dag_id=etl_pipeline, task_id=transfer_task, run_id=scheduled__2024-07-09T00:00:00+00:00, execution_date=20240709T000000, start_date=20240710T035825, end_date=20240710T035833
[2024-07-10T03:58:33.275+0000] {standard_task_runner.py:110} ERROR - Failed to execute job 5 for task transfer_task (Script failed with error: Traceback (most recent call last):
  File "/opt/***/etl_script/etl_script.py", line 42, in <module>
    with open(output_file, 'w', newline='') as f:
         ^^^^^^^^^^^^^^^^^^^^^^^^^^^^^^^^^^
FileNotFoundError: [Errno 2] No such file or directory: 'data/partsupp.csv'
; 202)
[2024-07-10T03:58:33.309+0000] {local_task_job_runner.py:240} INFO - Task exited with return code 1
[2024-07-10T03:58:33.321+0000] {taskinstance.py:3503} INFO - 0 downstream tasks scheduled from follow-on schedule check
[2024-07-10T03:58:33.322+0000] {local_task_job_runner.py:222} INFO - ::endgroup::
[2024-07-10T04:01:47.035+0000] {local_task_job_runner.py:120} INFO - ::group::Pre task execution logs
[2024-07-10T04:01:47.063+0000] {taskinstance.py:2076} INFO - Dependencies all met for dep_context=non-requeueable deps ti=<TaskInstance: etl_pipeline.transfer_task scheduled__2024-07-09T00:00:00+00:00 [queued]>
[2024-07-10T04:01:47.069+0000] {taskinstance.py:2076} INFO - Dependencies all met for dep_context=requeueable deps ti=<TaskInstance: etl_pipeline.transfer_task scheduled__2024-07-09T00:00:00+00:00 [queued]>
[2024-07-10T04:01:47.069+0000] {taskinstance.py:2306} INFO - Starting attempt 1 of 1
[2024-07-10T04:01:47.080+0000] {taskinstance.py:2330} INFO - Executing <Task(PythonOperator): transfer_task> on 2024-07-09 00:00:00+00:00
[2024-07-10T04:01:47.088+0000] {logging_mixin.py:188} WARNING - /home/***/.local/lib/python3.12/site-packages/***/task/task_runner/standard_task_runner.py:61 DeprecationWarning: This process (pid=190) is multi-threaded, use of fork() may lead to deadlocks in the child.
[2024-07-10T04:01:47.088+0000] {standard_task_runner.py:63} INFO - Started process 191 to run task
[2024-07-10T04:01:47.088+0000] {standard_task_runner.py:90} INFO - Running: ['***', 'tasks', 'run', 'etl_pipeline', 'transfer_task', 'scheduled__2024-07-09T00:00:00+00:00', '--job-id', '5', '--raw', '--subdir', 'DAGS_FOLDER/first_dag.py', '--cfg-path', '/tmp/tmp3dtn01ue']
[2024-07-10T04:01:47.090+0000] {standard_task_runner.py:91} INFO - Job 5: Subtask transfer_task
[2024-07-10T04:01:47.121+0000] {task_command.py:426} INFO - Running <TaskInstance: etl_pipeline.transfer_task scheduled__2024-07-09T00:00:00+00:00 [running]> on host fc4bb4e517d5
[2024-07-10T04:01:47.179+0000] {taskinstance.py:2648} INFO - Exporting env vars: AIRFLOW_CTX_DAG_OWNER='***' AIRFLOW_CTX_DAG_ID='etl_pipeline' AIRFLOW_CTX_TASK_ID='transfer_task' AIRFLOW_CTX_EXECUTION_DATE='2024-07-09T00:00:00+00:00' AIRFLOW_CTX_TRY_NUMBER='1' AIRFLOW_CTX_DAG_RUN_ID='scheduled__2024-07-09T00:00:00+00:00'
[2024-07-10T04:01:47.179+0000] {taskinstance.py:430} INFO - ::endgroup::
[2024-07-10T04:01:54.624+0000] {taskinstance.py:441} INFO - ::group::Post task execution logs
[2024-07-10T04:01:54.624+0000] {taskinstance.py:2905} ERROR - Task failed with exception
Traceback (most recent call last):
  File "/home/airflow/.local/lib/python3.12/site-packages/airflow/models/taskinstance.py", line 465, in _execute_task
    result = _execute_callable(context=context, **execute_callable_kwargs)
             ^^^^^^^^^^^^^^^^^^^^^^^^^^^^^^^^^^^^^^^^^^^^^^^^^^^^^^^^^^^^^
  File "/home/airflow/.local/lib/python3.12/site-packages/airflow/models/taskinstance.py", line 432, in _execute_callable
    return execute_callable(context=context, **execute_callable_kwargs)
           ^^^^^^^^^^^^^^^^^^^^^^^^^^^^^^^^^^^^^^^^^^^^^^^^^^^^^^^^^^^^
  File "/home/airflow/.local/lib/python3.12/site-packages/airflow/models/baseoperator.py", line 401, in wrapper
    return func(self, *args, **kwargs)
           ^^^^^^^^^^^^^^^^^^^^^^^^^^^
  File "/home/airflow/.local/lib/python3.12/site-packages/airflow/operators/python.py", line 235, in execute
    return_value = self.execute_callable()
                   ^^^^^^^^^^^^^^^^^^^^^^^
  File "/home/airflow/.local/lib/python3.12/site-packages/airflow/operators/python.py", line 252, in execute_callable
    return self.python_callable(*self.op_args, **self.op_kwargs)
           ^^^^^^^^^^^^^^^^^^^^^^^^^^^^^^^^^^^^^^^^^^^^^^^^^^^^^
  File "/opt/airflow/dags/first_dag.py", line 32, in run_etl_script
    raise Exception(f"Script failed with error: {result.stderr}")
Exception: Script failed with error: Traceback (most recent call last):
  File "/opt/***/etl_script/etl_script.py", line 42, in <module>
    with open(output_file, 'w', newline='') as f:
         ^^^^^^^^^^^^^^^^^^^^^^^^^^^^^^^^^^
PermissionError: [Errno 13] Permission denied: '/opt/***/etl_script/data/partsupp.csv'

[2024-07-10T04:01:54.631+0000] {taskinstance.py:1206} INFO - Marking task as FAILED. dag_id=etl_pipeline, task_id=transfer_task, run_id=scheduled__2024-07-09T00:00:00+00:00, execution_date=20240709T000000, start_date=20240710T040147, end_date=20240710T040154
[2024-07-10T04:01:54.640+0000] {standard_task_runner.py:110} ERROR - Failed to execute job 5 for task transfer_task (Script failed with error: Traceback (most recent call last):
  File "/opt/***/etl_script/etl_script.py", line 42, in <module>
    with open(output_file, 'w', newline='') as f:
         ^^^^^^^^^^^^^^^^^^^^^^^^^^^^^^^^^^
PermissionError: [Errno 13] Permission denied: '/opt/***/etl_script/data/partsupp.csv'
; 191)
[2024-07-10T04:01:54.668+0000] {local_task_job_runner.py:240} INFO - Task exited with return code 1
[2024-07-10T04:01:54.678+0000] {taskinstance.py:3503} INFO - 0 downstream tasks scheduled from follow-on schedule check
[2024-07-10T04:01:54.679+0000] {local_task_job_runner.py:222} INFO - ::endgroup::
[2024-07-10T04:05:53.915+0000] {local_task_job_runner.py:120} INFO - ::group::Pre task execution logs
[2024-07-10T04:05:53.948+0000] {taskinstance.py:2076} INFO - Dependencies all met for dep_context=non-requeueable deps ti=<TaskInstance: etl_pipeline.transfer_task scheduled__2024-07-09T00:00:00+00:00 [queued]>
[2024-07-10T04:05:53.958+0000] {taskinstance.py:2076} INFO - Dependencies all met for dep_context=requeueable deps ti=<TaskInstance: etl_pipeline.transfer_task scheduled__2024-07-09T00:00:00+00:00 [queued]>
[2024-07-10T04:05:53.958+0000] {taskinstance.py:2306} INFO - Starting attempt 1 of 1
[2024-07-10T04:05:53.971+0000] {taskinstance.py:2330} INFO - Executing <Task(PythonOperator): transfer_task> on 2024-07-09 00:00:00+00:00
[2024-07-10T04:05:53.976+0000] {standard_task_runner.py:90} INFO - Running: ['***', 'tasks', 'run', 'etl_pipeline', 'transfer_task', 'scheduled__2024-07-09T00:00:00+00:00', '--job-id', '6', '--raw', '--subdir', 'DAGS_FOLDER/first_dag.py', '--cfg-path', '/tmp/tmpmia68t1z']
[2024-07-10T04:05:53.978+0000] {standard_task_runner.py:91} INFO - Job 6: Subtask transfer_task
[2024-07-10T04:05:53.979+0000] {logging_mixin.py:188} WARNING - /home/***/.local/lib/python3.12/site-packages/***/task/task_runner/standard_task_runner.py:61 DeprecationWarning: This process (pid=203) is multi-threaded, use of fork() may lead to deadlocks in the child.
[2024-07-10T04:05:53.979+0000] {standard_task_runner.py:63} INFO - Started process 204 to run task
[2024-07-10T04:05:54.057+0000] {task_command.py:426} INFO - Running <TaskInstance: etl_pipeline.transfer_task scheduled__2024-07-09T00:00:00+00:00 [running]> on host f0c32192715b
[2024-07-10T04:05:54.131+0000] {taskinstance.py:2648} INFO - Exporting env vars: AIRFLOW_CTX_DAG_OWNER='***' AIRFLOW_CTX_DAG_ID='etl_pipeline' AIRFLOW_CTX_TASK_ID='transfer_task' AIRFLOW_CTX_EXECUTION_DATE='2024-07-09T00:00:00+00:00' AIRFLOW_CTX_TRY_NUMBER='1' AIRFLOW_CTX_DAG_RUN_ID='scheduled__2024-07-09T00:00:00+00:00'
[2024-07-10T04:05:54.131+0000] {taskinstance.py:430} INFO - ::endgroup::
[2024-07-10T04:06:00.677+0000] {taskinstance.py:441} INFO - ::group::Post task execution logs
[2024-07-10T04:06:00.677+0000] {taskinstance.py:2905} ERROR - Task failed with exception
Traceback (most recent call last):
  File "/home/airflow/.local/lib/python3.12/site-packages/airflow/models/taskinstance.py", line 465, in _execute_task
    result = _execute_callable(context=context, **execute_callable_kwargs)
             ^^^^^^^^^^^^^^^^^^^^^^^^^^^^^^^^^^^^^^^^^^^^^^^^^^^^^^^^^^^^^
  File "/home/airflow/.local/lib/python3.12/site-packages/airflow/models/taskinstance.py", line 432, in _execute_callable
    return execute_callable(context=context, **execute_callable_kwargs)
           ^^^^^^^^^^^^^^^^^^^^^^^^^^^^^^^^^^^^^^^^^^^^^^^^^^^^^^^^^^^^
  File "/home/airflow/.local/lib/python3.12/site-packages/airflow/models/baseoperator.py", line 401, in wrapper
    return func(self, *args, **kwargs)
           ^^^^^^^^^^^^^^^^^^^^^^^^^^^
  File "/home/airflow/.local/lib/python3.12/site-packages/airflow/operators/python.py", line 235, in execute
    return_value = self.execute_callable()
                   ^^^^^^^^^^^^^^^^^^^^^^^
  File "/home/airflow/.local/lib/python3.12/site-packages/airflow/operators/python.py", line 252, in execute_callable
    return self.python_callable(*self.op_args, **self.op_kwargs)
           ^^^^^^^^^^^^^^^^^^^^^^^^^^^^^^^^^^^^^^^^^^^^^^^^^^^^^
  File "/opt/airflow/dags/first_dag.py", line 32, in run_etl_script
    raise Exception(f"Script failed with error: {result.stderr}")
Exception: Script failed with error: Traceback (most recent call last):
  File "/opt/***/etl_script/etl_script.py", line 45, in <module>
    with open(output_file, 'w', newline='') as f:
         ^^^^^^^^^^^^^^^^^^^^^^^^^^^^^^^^^^
PermissionError: [Errno 13] Permission denied: '/opt/***/etl_script/data/partsupp.csv'

[2024-07-10T04:06:00.684+0000] {taskinstance.py:1206} INFO - Marking task as FAILED. dag_id=etl_pipeline, task_id=transfer_task, run_id=scheduled__2024-07-09T00:00:00+00:00, execution_date=20240709T000000, start_date=20240710T040553, end_date=20240710T040600
[2024-07-10T04:06:00.694+0000] {standard_task_runner.py:110} ERROR - Failed to execute job 6 for task transfer_task (Script failed with error: Traceback (most recent call last):
  File "/opt/***/etl_script/etl_script.py", line 45, in <module>
    with open(output_file, 'w', newline='') as f:
         ^^^^^^^^^^^^^^^^^^^^^^^^^^^^^^^^^^
PermissionError: [Errno 13] Permission denied: '/opt/***/etl_script/data/partsupp.csv'
; 204)
[2024-07-10T04:06:00.726+0000] {local_task_job_runner.py:240} INFO - Task exited with return code 1
[2024-07-10T04:06:00.738+0000] {taskinstance.py:3503} INFO - 0 downstream tasks scheduled from follow-on schedule check
[2024-07-10T04:06:00.742+0000] {local_task_job_runner.py:222} INFO - ::endgroup::
