[2024-07-10T04:14:57.549+0000] {local_task_job_runner.py:120} INFO - ::group::Pre task execution logs
[2024-07-10T04:14:57.576+0000] {taskinstance.py:2076} INFO - Dependencies all met for dep_context=non-requeueable deps ti=<TaskInstance: etl_pipeline_v1.transfer_task manual__2024-07-10T04:14:27.789034+00:00 [queued]>
[2024-07-10T04:14:57.582+0000] {taskinstance.py:2076} INFO - Dependencies all met for dep_context=requeueable deps ti=<TaskInstance: etl_pipeline_v1.transfer_task manual__2024-07-10T04:14:27.789034+00:00 [queued]>
[2024-07-10T04:14:57.583+0000] {taskinstance.py:2306} INFO - Starting attempt 1 of 1
[2024-07-10T04:14:57.600+0000] {taskinstance.py:2330} INFO - Executing <Task(PythonOperator): transfer_task> on 2024-07-10 04:14:27.789034+00:00
[2024-07-10T04:14:57.609+0000] {logging_mixin.py:188} WARNING - /home/***/.local/lib/python3.12/site-packages/***/task/task_runner/standard_task_runner.py:61 DeprecationWarning: This process (pid=431) is multi-threaded, use of fork() may lead to deadlocks in the child.
[2024-07-10T04:14:57.607+0000] {standard_task_runner.py:90} INFO - Running: ['***', 'tasks', 'run', 'etl_pipeline_v1', 'transfer_task', 'manual__2024-07-10T04:14:27.789034+00:00', '--job-id', '10', '--raw', '--subdir', 'DAGS_FOLDER/first_dag.py', '--cfg-path', '/tmp/tmpejc7cgit']
[2024-07-10T04:14:57.610+0000] {standard_task_runner.py:91} INFO - Job 10: Subtask transfer_task
[2024-07-10T04:14:57.610+0000] {standard_task_runner.py:63} INFO - Started process 433 to run task
[2024-07-10T04:14:57.643+0000] {task_command.py:426} INFO - Running <TaskInstance: etl_pipeline_v1.transfer_task manual__2024-07-10T04:14:27.789034+00:00 [running]> on host f0c32192715b
[2024-07-10T04:14:57.706+0000] {taskinstance.py:2648} INFO - Exporting env vars: AIRFLOW_CTX_DAG_OWNER='***' AIRFLOW_CTX_DAG_ID='etl_pipeline_v1' AIRFLOW_CTX_TASK_ID='transfer_task' AIRFLOW_CTX_EXECUTION_DATE='2024-07-10T04:14:27.789034+00:00' AIRFLOW_CTX_TRY_NUMBER='1' AIRFLOW_CTX_DAG_RUN_ID='manual__2024-07-10T04:14:27.789034+00:00'
[2024-07-10T04:14:57.707+0000] {taskinstance.py:430} INFO - ::endgroup::
[2024-07-10T04:14:59.719+0000] {taskinstance.py:441} INFO - ::group::Post task execution logs
[2024-07-10T04:14:59.719+0000] {taskinstance.py:2905} ERROR - Task failed with exception
Traceback (most recent call last):
  File "/home/airflow/.local/lib/python3.12/site-packages/airflow/models/taskinstance.py", line 465, in _execute_task
    result = _execute_callable(context=context, **execute_callable_kwargs)
             ^^^^^^^^^^^^^^^^^^^^^^^^^^^^^^^^^^^^^^^^^^^^^^^^^^^^^^^^^^^^^
  File "/home/airflow/.local/lib/python3.12/site-packages/airflow/models/taskinstance.py", line 432, in _execute_callable
    return execute_callable(context=context, **execute_callable_kwargs)
           ^^^^^^^^^^^^^^^^^^^^^^^^^^^^^^^^^^^^^^^^^^^^^^^^^^^^^^^^^^^^
  File "/home/airflow/.local/lib/python3.12/site-packages/airflow/models/baseoperator.py", line 401, in wrapper
    return func(self, *args, **kwargs)
           ^^^^^^^^^^^^^^^^^^^^^^^^^^^
  File "/home/airflow/.local/lib/python3.12/site-packages/airflow/operators/python.py", line 235, in execute
    return_value = self.execute_callable()
                   ^^^^^^^^^^^^^^^^^^^^^^^
  File "/home/airflow/.local/lib/python3.12/site-packages/airflow/operators/python.py", line 252, in execute_callable
    return self.python_callable(*self.op_args, **self.op_kwargs)
           ^^^^^^^^^^^^^^^^^^^^^^^^^^^^^^^^^^^^^^^^^^^^^^^^^^^^^
  File "/opt/airflow/dags/first_dag.py", line 32, in run_etl_script
    raise Exception(f"Script failed with error: {result.stderr}")
Exception: Script failed with error: Traceback (most recent call last):
  File "/opt/***/etl_script/etl_script.py", line 27, in <module>
    os.makedirs(data_dir, exist_ok=True)
  File "<frozen os>", line 225, in makedirs
PermissionError: [Errno 13] Permission denied: '/opt/***/etl_script/data/'

[2024-07-10T04:14:59.726+0000] {taskinstance.py:1206} INFO - Marking task as FAILED. dag_id=etl_pipeline_v1, task_id=transfer_task, run_id=manual__2024-07-10T04:14:27.789034+00:00, execution_date=20240710T041427, start_date=20240710T041457, end_date=20240710T041459
[2024-07-10T04:14:59.737+0000] {standard_task_runner.py:110} ERROR - Failed to execute job 10 for task transfer_task (Script failed with error: Traceback (most recent call last):
  File "/opt/***/etl_script/etl_script.py", line 27, in <module>
    os.makedirs(data_dir, exist_ok=True)
  File "<frozen os>", line 225, in makedirs
PermissionError: [Errno 13] Permission denied: '/opt/***/etl_script/data/'
; 433)
[2024-07-10T04:14:59.750+0000] {local_task_job_runner.py:240} INFO - Task exited with return code 1
[2024-07-10T04:14:59.762+0000] {taskinstance.py:3503} INFO - 0 downstream tasks scheduled from follow-on schedule check
[2024-07-10T04:14:59.765+0000] {local_task_job_runner.py:222} INFO - ::endgroup::
